File: Datos/Capacidad_calorifica.txt
CLOSED
Version	0.4
Language	English
Mode	Standard
Run	1
RunSerial	1259
Instrument	DSC Q2000 V24.10 Build 122
Module	DSC Standard Cell RC
Operator	Guille U
File	\\Dscq2000\ta\USUARIOS\Servicios\David Cordova\20220901a - caparazon.001
ProcName	Diego Franco
InstSerial	2000-3010
Sample	Caparazon
Size	17.7000	mg
PanMass	51.300 51.100  mg
PanResist	Automatic Automatic  K/W
PanFactor	Default Default
Method	Diego Franco
Comment	caparazon-vacio
Xcomment	Pan: Tzero Aluminum
Xcomment	Gas1: Argon 20.0 ml/min
Xcomment	Gas2: Nitrogen 20.0 ml/min
Text
Exotherm	DOWN
Kcell	1.00690
Cpconst	Standard: 1.000
Calib	101.2342
TempCal	1	pts	156.27	156.60
TzeroDt	-80.0425 -0.0054 1.4168
TzeroDtz	-80.0425 0.0099 2.0472
InstCalFile	Tzero: \\Dscq2000\ta\USUARIOS\Calib\026 Calib Ar 15Cmin -80-250C 20 mlmin\CALIBRATION\4856_RCS (90)_09_01_2022 10_44_19.TZR
InstCalFile	Baseline: \\Dscq2000\ta\USUARIOS\Calib\026 Calib Ar 15Cmin -80-250C 20 mlmin\vacia.001
InstCalFile	Sapphire: \\Dscq2000\ta\USUARIOS\Calib\026 Calib Ar 15Cmin -80-250C 20 mlmin\zafiro.001
InstCalDate	Tzero 2022-09-01 Time 10:44:19
TempRange	-80.04 to 247.35 øC at 14.98 øC/min Heat Only
AutoZero	Delta T Offset 0.000 uV
AutoZero	Delta T0 Offset 0.000 uV
MultiptCal	0
MultiPtDesc	0) Not set
AutoCellConst	Calibration Date 2022-09-01 10:45:58
Controls	Gas 1  Event Off  Sampling 0.2
Cell#	RC-04856
CoolingUnit	RCS (90)
SelHeatFlow	Heat Flow T4P (mW)
AutoLidII	Installed
AutoAnalysis	Off
MacroFile
Nsig	5
Sig1	Time (min)
Sig2	Temperature (øC)
Sig3	Heat Flow (mW)
Sig4	Heat Capacity (mJ/øC)
Sig5	Sample Purge Flow (mL/min)
Date	2022-09-01
Time	12:42:25
OrgMethod	1: Sampling interval 0.10 s/pt
OrgMethod	2: Select gas 1
OrgMethod	3: Mass flow 20.00 mL/min
OrgMethod	4: Equilibrate at -20.00 øC
OrgMethod	5: Isothermal for 10.00 min
OrgMethod	6: Ramp 15.00 øC/min to 100.00 øC
OrgMethod	7: Isothermal for 10.00 min
OrgFile	C:\TA\USUARIOS\Servicios\David Cordova\20220901a - caparazon.001
StartOfData
.001333326	-19.96270	-0.3069528	0.0000000	19.95855
0.02800000	-19.96295	-0.2949620	0.0000000	20.12242
0.05466665	-19.96809	-0.2867600	0.0000000	20.06153
0.08133332	-19.96802	-0.2785719	0.0000000	19.99688
0.1080000	-19.96958	-0.2731491	0.0000000	19.87582
0.1346667	-19.97066	-0.2676888	0.0000000	20.09862
0.1613333	-19.97311	-0.2609689	0.0000000	19.99331
0.1880000	-19.97488	-0.2555180	0.0000000	19.91982
0.2146666	-19.97649	-0.2517858	0.0000000	20.11343
0.2413333	-19.97830	-0.2478086	0.0000000	19.96489
0.2680000	-19.97875	-0.2444209	0.0000000	19.90674
0.2946666	-19.97858	-0.2407289	0.0000000	20.10804
0.3213334	-19.98044	-0.2370700	0.0000000	20.00131
0.3480000	-19.98032	-0.2334697	0.0000000	19.86951
0.3746667	-19.98196	-0.2299814	0.0000000	20.18465
0.4013333	-19.98369	-0.2266025	0.0000000	19.97564
0.4280000	-19.98496	-0.2233537	0.0000000	19.87166
0.4546667	-19.98467	-0.2200851	0.0000000	20.14957
0.4813333	-19.98381	-0.2169362	0.0000000	19.89975
0.5080000	-19.98530	-0.2140040	0.0000000	19.81161
0.5346666	-19.98477	-0.2110893	0.0000000	20.20098
0.5613334	-19.98555	-0.2084640	0.0000000	20.00009
0.5880000	-19.98741	-0.2057332	0.0000000	19.83391
0.6146668	-19.98661	-0.2031831	0.0000000	20.15761
0.6413332	-19.98800	-0.2008896	0.0000000	20.01598
0.6680000	-19.98814	-0.1985691	0.0000000	19.84837
0.6946668	-19.98965	-0.1964696	0.0000000	20.23351
0.7213332	-19.99029	-0.1946379	0.0000000	19.94772
0.7480000	-19.98976	-0.1926946	0.0000000	19.81221
0.7746668	-19.98944	-0.1907489	0.0000000	20.22534
0.8013332	-19.99012	-0.1888610	0.0000000	19.95573
0.8280000	-19.99149	-0.1871219	0.0000000	19.85985
0.8546668	-19.99087	-0.1854728	0.0000000	19.96088
0.8813332	-19.99219	-0.1839797	0.0000000	19.94638
0.9080000	-19.98981	-0.1825595	0.0000000	19.82736
0.9346666	-19.99167	-0.1811893	0.0000000	20.14711
0.9613334	-19.99168	-0.1797594	0.0000000	19.93998
0.9880000	-19.99289	-0.1784483	0.0000000	20.03311
1.014667	-19.99367	-0.1773840	0.0000000	20.18840
1.041333	-19.99294	-0.1761928	0.0000000	19.94626
1.068000	-19.99142	-0.1752207	0.0000000	20.01342
1.094666	-19.99406	-0.1741866	0.0000000	19.96057
1.121333	-19.99318	-0.1731964	0.0000000	19.93102
1.148000	-19.99412	-0.1723022	0.0000000	20.06646
1.174666	-19.99436	-0.1713301	0.0000000	20.03289
1.201333	-19.99321	-0.1704567	0.0000000	19.91088
1.228000	-19.99428	-0.1697925	0.0000000	20.15444
1.254667	-19.99466	-0.1691089	0.0000000	19.98448
1.281333	-19.99650	-0.1683738	0.0000000	19.87432
1.308000	-19.99539	-0.1677446	0.0000000	20.00259
1.334667	-19.99443	-0.1670626	0.0000000	20.15370
1.361333	-19.99487	-0.1664823	0.0000000	19.88041
1.388000	-19.99530	-0.1658799	0.0000000	19.92792
1.414666	-19.99478	-0.1653155	0.0000000	20.18335
1.441333	-19.99584	-0.1647423	0.0000000	19.87923
1.468000	-19.99768	-0.1642931	0.0000000	19.91262
1.494667	-19.99656	-0.1638074	0.0000000	20.14401
1.521333	-19.99562	-0.1633112	0.0000000	20.06716
1.548000	-19.99414	-0.1629293	0.0000000	19.99965
1.574666	-19.99582	-0.1623999	0.0000000	20.08894
1.601334	-19.99788	-0.1619212	0.0000000	20.00828
1.628000	-19.99689	-0.1615038	0.0000000	20.13641
1.654667	-19.99734	-0.1611607	0.0000000	19.92302
1.681333	-19.99762	-0.1609641	0.0000000	19.92238
1.708000	-19.99676	-0.1605393	0.0000000	20.11340
1.734666	-19.99732	-0.1600701	0.0000000	19.86203
1.761333	-19.99734	-0.1598420	0.0000000	20.12302
1.788000	-19.99651	-0.1594180	0.0000000	20.03351
1.814666	-19.99580	-0.1591465	0.0000000	19.90991
1.841333	-19.99763	-0.1588534	0.0000000	20.07725
1.868000	-19.99706	-0.1585583	0.0000000	19.91277
1.894667	-19.99770	-0.1582652	0.0000000	19.98799
1.921333	-19.99759	-0.1579883	0.0000000	20.20056
1.948000	-19.99888	-0.1578133	0.0000000	19.91165
1.974666	-19.99772	-0.1575948	0.0000000	19.95207
2.001333	-19.99899	-0.1573297	0.0000000	20.17239
2.028000	-19.99926	-0.1571543	0.0000000	19.90715
2.054667	-19.99962	-0.1569698	0.0000000	19.96629
2.081333	-19.99742	-0.1568338	0.0000000	20.18512
2.108000	-19.99989	-0.1567596	0.0000000	19.87753
2.134666	-19.99872	-0.1563618	0.0000000	19.92849
2.161333	-19.99974	-0.1560927	0.0000000	20.10643
2.188000	-19.99773	-0.1557205	0.0000000	19.96108
2.214666	-19.99873	-0.1557431	0.0000000	20.04419
2.241333	-19.99758	-0.1553627	0.0000000	19.91665
2.268000	-19.99838	-0.1549410	0.0000000	20.02361
2.294667	-20.00051	-0.1546074	0.0000000	20.21142
2.321333	-19.99850	-0.1544599	0.0000000	19.87528
2.348000	-19.99913	-0.1542609	0.0000000	19.98132
2.374666	-19.99893	-0.1541011	0.0000000	20.16045
2.401333	-19.99886	-0.1539369	0.0000000	19.87684
2.428000	-19.99899	-0.1537592	0.0000000	19.93161
2.454666	-19.99809	-0.1536306	0.0000000	20.17581
2.481333	-19.99759	-0.1534975	0.0000000	19.88378
2.508000	-19.99990	-0.1532345	0.0000000	20.08402
2.534667	-19.99941	-0.1530471	0.0000000	20.00284
2.561334	-20.00232	-0.1527022	0.0000000	19.93408
2.588000	-20.00014	-0.1527482	0.0000000	20.14446
2.614667	-20.00012	-0.1525379	0.0000000	19.84854
2.641333	-20.00040	-0.1524611	0.0000000	19.97134
2.668000	-19.99990	-0.1524677	0.0000000	20.13535
2.694667	-19.99996	-0.1522598	0.0000000	19.95537
2.721333	-20.00052	-0.1519065	0.0000000	19.97426
2.748000	-20.00069	-0.1518080	0.0000000	20.19558
2.774667	-20.00090	-0.1516705	0.0000000	19.81248
2.801333	-19.99986	-0.1514676	0.0000000	20.13182
2.828000	-20.00081	-0.1513374	0.0000000	19.95236
2.854667	-20.00046	-0.1512834	0.0000000	19.98278
2.881333	-20.00166	-0.1511436	0.0000000	20.12979
2.908000	-20.00024	-0.1510164	0.0000000	19.87147
2.934667	-20.00199	-0.1509598	0.0000000	20.01004
2.961333	-20.00116	-0.1508236	0.0000000	20.17550
2.988000	-20.00095	-0.1506851	0.0000000	19.87739
3.014666	-20.00035	-0.1505388	0.0000000	19.97060
3.041333	-20.00139	-0.1503427	0.0000000	20.13426
3.068000	-20.00104	-0.1502145	0.0000000	19.86980
3.094667	-20.00118	-0.1500495	0.0000000	20.08800
3.121333	-20.00050	-0.1497730	0.0000000	19.88144
3.148000	-20.00176	-0.1497694	0.0000000	19.99080
3.174667	-20.00117	-0.1496179	0.0000000	20.17325
3.201333	-19.99992	-0.1494537	0.0000000	19.91577
3.228000	-20.00098	-0.1493248	0.0000000	19.95770
3.254666	-20.00236	-0.1491159	0.0000000	20.17953
3.281334	-20.00121	-0.1489869	0.0000000	19.87372
3.308000	-20.00065	-0.1488187	0.0000000	20.08042
3.334667	-20.00242	-0.1486990	0.0000000	19.97266
3.361334	-20.00120	-0.1485948	0.0000000	19.94601
3.388000	-20.00065	-0.1483961	0.0000000	20.14517
3.414667	-20.00177	-0.1482997	0.0000000	19.89604
3.441333	-20.00126	-0.1482471	0.0000000	19.97371
3.468000	-20.00092	-0.1481226	0.0000000	20.22498
3.494667	-20.00080	-0.1481509	0.0000000	19.85897
3.521333	-20.00115	-0.1478992	0.0000000	19.98466
3.548000	-20.00185	-0.1478818	0.0000000	19.97635
3.574667	-20.00271	-0.1477352	0.0000000	19.93916
3.601333	-20.00066	-0.1475182	0.0000000	20.12194
3.628000	-20.00191	-0.1473712	0.0000000	19.90450
3.654666	-20.00304	-0.1471636	0.0000000	19.94398
3.681333	-20.00024	-0.1471481	0.0000000	20.19666
3.708000	-20.00225	-0.1469902	0.0000000	19.88685
3.734666	-20.00126	-0.1468588	0.0000000	19.92888
3.761333	-20.00228	-0.1466438	0.0000000	20.00384
3.788000	-20.00181	-0.1466255	0.0000000	19.94374
3.814667	-20.00291	-0.1463716	0.0000000	20.13043
3.841333	-20.00139	-0.1464538	0.0000000	19.88082
3.868000	-20.00241	-0.1462116	0.0000000	19.91650
3.894667	-20.00299	-0.1461710	0.0000000	20.15664
3.921333	-20.00351	-0.1460431	0.0000000	19.94291
3.948000	-20.00117	-0.1460632	0.0000000	20.11280
3.974667	-20.00270	-0.1459424	0.0000000	19.97599
4.001333	-20.00164	-0.1457602	0.0000000	19.99938
4.028000	-20.00229	-0.1456791	0.0000000	20.16236
4.054666	-20.00285	-0.1455742	0.0000000	20.16578
4.081333	-20.00229	-0.1455347	0.0000000	19.86659
4.108000	-20.00222	-0.1454495	0.0000000	19.97156
4.134666	-20.00323	-0.1453194	0.0000000	20.06555
4.161334	-20.00116	-0.1451794	0.0000000	19.83542
4.188000	-20.00163	-0.1451381	0.0000000	20.10622
4.214667	-20.00321	-0.1449806	0.0000000	19.93383
4.241334	-20.00329	-0.1448202	0.0000000	19.97292
4.268000	-20.00244	-0.1448022	0.0000000	20.09601
4.294667	-20.00246	-0.1447592	0.0000000	19.92320
4.321334	-20.00158	-0.1447431	0.0000000	19.97982
4.348000	-20.00293	-0.1445882	0.0000000	19.99344
4.374667	-20.00259	-0.1445301	0.0000000	19.98062
4.401334	-20.00295	-0.1445447	0.0000000	20.15475
4.428000	-20.00320	-0.1444826	0.0000000	19.91580
4.454666	-20.00277	-0.1442976	0.0000000	19.93876
4.481333	-20.00272	-0.1442202	0.0000000	20.16691
4.508000	-20.00345	-0.1441519	0.0000000	19.86429
4.534666	-20.00244	-0.1440991	0.0000000	20.24442
4.561333	-20.00330	-0.1441162	0.0000000	19.90664
4.588000	-20.00413	-0.1439180	0.0000000	19.92966
4.614666	-20.00161	-0.1438578	0.0000000	20.19847
4.641333	-20.00375	-0.1437939	0.0000000	19.85192
4.668000	-20.00315	-0.1436746	0.0000000	19.96910
4.694667	-20.00328	-0.1435149	0.0000000	19.96948
4.721334	-20.00280	-0.1435035	0.0000000	19.98462
4.748000	-20.00301	-0.1434104	0.0000000	20.17367
4.774667	-20.00201	-0.1433407	0.0000000	19.90109
4.801334	-20.00280	-0.1433132	0.0000000	19.94713
4.828000	-20.00361	-0.1432418	0.0000000	20.10585
4.854667	-20.00398	-0.1430129	0.0000000	19.88408
4.881333	-20.00356	-0.1431901	0.0000000	20.12544
4.908000	-20.00262	-0.1431120	0.0000000	19.82684
4.934666	-20.00309	-0.1430282	0.0000000	19.95005
4.961334	-20.00367	-0.1430901	0.0000000	20.16149
4.988000	-20.00192	-0.1428440	0.0000000	19.89539
5.014667	-20.00442	-0.1428042	0.0000000	20.09757
5.041333	-20.00296	-0.1426968	0.0000000	19.90664
5.068000	-20.00364	-0.1427164	0.0000000	19.97219
5.094666	-20.00292	-0.1427017	0.0000000	20.14356
5.121333	-20.00371	-0.1426746	0.0000000	19.87841
5.148000	-20.00330	-0.1426048	0.0000000	20.03379
5.174667	-20.00498	-0.1424553	0.0000000	19.96964
5.201334	-20.00356	-0.1424270	0.0000000	19.99448
5.228000	-20.00414	-0.1423582	0.0000000	20.16972
5.254668	-20.00438	-0.1423123	0.0000000	19.88671
5.281334	-20.00342	-0.1422750	0.0000000	19.96713
5.308000	-20.00444	-0.1421657	0.0000000	20.11238
5.334668	-20.00242	-0.1421374	0.0000000	19.94994
5.361334	-20.00344	-0.1420274	0.0000000	20.12467
5.388000	-20.00304	-0.1419340	0.0000000	19.87964
5.414668	-20.00391	-0.1418483	0.0000000	19.96720
5.441334	-20.00309	-0.1417352	0.0000000	20.11797
5.468000	-20.00333	-0.1418422	0.0000000	19.94736
5.494668	-20.00271	-0.1417783	0.0000000	20.19125
5.521332	-20.00475	-0.1416574	0.0000000	19.89656
5.548000	-20.00356	-0.1415410	0.0000000	19.97675
5.574668	-20.00442	-0.1416286	0.0000000	20.14362
5.601332	-20.00471	-0.1414668	0.0000000	19.87298
5.628000	-20.00493	-0.1413455	0.0000000	20.11439
5.654668	-20.00306	-0.1413401	0.0000000	19.90388
5.681334	-20.00294	-0.1414428	0.0000000	19.96795
5.708000	-20.00301	-0.1413705	0.0000000	20.20996
5.734668	-20.00320	-0.1411456	0.0000000	19.93482
5.761334	-20.00409	-0.1412254	0.0000000	20.14051
5.788000	-20.00469	-0.1410710	0.0000000	19.87386
5.814668	-20.00513	-0.1410800	0.0000000	20.01384
5.841334	-20.00493	-0.1409509	0.0000000	20.12834
5.868000	-20.00371	-0.1408833	0.0000000	19.85562
5.894668	-20.00438	-0.1408486	0.0000000	20.03519
5.921332	-20.00431	-0.1408268	0.0000000	19.90916
5.948000	-20.00284	-0.1407594	0.0000000	19.90925
5.974668	-20.00530	-0.1405204	0.0000000	20.08164
6.001332	-20.00414	-0.1404546	0.0000000	19.89817
6.028000	-20.00514	-0.1403304	0.0000000	20.13532
6.054668	-20.00503	-0.1402094	0.0000000	19.90350
6.081332	-20.00369	-0.1401747	0.0000000	19.97531
6.108000	-20.00398	-0.1399199	0.0000000	20.13962
6.134668	-20.00389	-0.1398069	0.0000000	19.91155
6.161334	-20.00423	-0.1397936	0.0000000	20.20984
6.188000	-20.00527	-0.1398045	0.0000000	19.86504
6.214668	-20.00494	-0.1395304	0.0000000	20.00321
6.241334	-20.00511	-0.1395372	0.0000000	20.01154
6.268000	-20.00490	-0.1395798	0.0000000	19.97022
6.294668	-20.00499	-0.1393363	0.0000000	20.21945
6.321332	-20.00548	-0.1392642	0.0000000	19.84820
6.348000	-20.00458	-0.1391163	0.0000000	19.95111
6.374668	-20.00706	-0.1390525	0.0000000	20.02203
6.401334	-20.00620	-0.1389764	0.0000000	20.04239
6.428000	-20.00648	-0.1389696	0.0000000	20.18647
6.454668	-20.00527	-0.1390241	0.0000000	19.84229
6.481332	-20.00619	-0.1389332	0.0000000	19.92291
6.508000	-20.00566	-0.1389322	0.0000000	20.04643
6.534668	-20.00550	-0.1390044	0.0000000	19.93724
6.561334	-20.00471	-0.1388906	0.0000000	19.97428
6.588000	-20.00476	-0.1388111	0.0000000	20.19826
6.614668	-20.00545	-0.1386851	0.0000000	19.91435
6.641332	-20.00458	-0.1386265	0.0000000	20.12254
6.668000	-20.00403	-0.1385583	0.0000000	19.80758
6.694668	-20.00362	-0.1385236	0.0000000	19.95682
6.721332	-20.00349	-0.1384473	0.0000000	20.04927
6.748000	-20.00452	-0.1383083	0.0000000	19.97064
6.774668	-20.00580	-0.1382516	0.0000000	20.15645
6.801334	-20.00441	-0.1380905	0.0000000	19.86851
6.828000	-20.00579	-0.1380844	0.0000000	19.97490
6.854668	-20.00522	-0.1380654	0.0000000	19.98479
6.881332	-20.00598	-0.1380135	0.0000000	19.93497
6.908000	-20.00477	-0.1380580	0.0000000	20.18069
6.934668	-20.00542	-0.1379068	0.0000000	19.92852
6.961334	-20.00374	-0.1378838	0.0000000	20.09431
6.988000	-20.00419	-0.1379098	0.0000000	19.82072
7.014668	-20.00418	-0.1378166	0.0000000	19.92558
7.041332	-20.00588	-0.1378121	0.0000000	20.18394
7.068000	-20.00592	-0.1377147	0.0000000	19.84444
7.094666	-20.00479	-0.1377944	0.0000000	20.11101
7.121332	-20.00599	-0.1377099	0.0000000	19.84691
7.148000	-20.00711	-0.1376959	0.0000000	19.95923
7.174668	-20.00641	-0.1375919	0.0000000	20.04042
7.201334	-20.00545	-0.1375828	0.0000000	19.99277
7.228000	-20.00422	-0.1375778	0.0000000	20.20785
7.254668	-20.00474	-0.1375029	0.0000000	19.95713
7.281332	-20.00488	-0.1374997	0.0000000	20.00699
7.308000	-20.00596	-0.1374642	0.0000000	19.86496
7.334668	-20.00578	-0.1374421	0.0000000	19.90700
7.361334	-20.00534	-0.1374076	0.0000000	20.16638
7.388000	-20.00424	-0.1373939	0.0000000	19.89683
7.414668	-20.00624	-0.1372894	0.0000000	20.11729
7.441332	-20.00519	-0.1371722	0.0000000	19.81340
7.468000	-20.00647	-0.1370646	0.0000000	19.94291
7.494666	-20.00523	-0.1369944	0.0000000	20.00667
7.521332	-20.00752	-0.1369945	0.0000000	19.99132
7.548000	-20.00516	-0.1369998	0.0000000	20.12067
7.574668	-20.00581	-0.1370266	0.0000000	19.91263
7.601332	-20.00654	-0.1368510	0.0000000	20.04600
7.628000	-20.00637	-0.1368537	0.0000000	19.91345
7.654668	-20.00660	-0.1368413	0.0000000	19.81622
7.681334	-20.00552	-0.1367806	0.0000000	20.14281
7.708000	-20.00602	-0.1366649	0.0000000	19.89883
7.734668	-20.00574	-0.1366344	0.0000000	20.13791
7.761334	-20.00414	-0.1366980	0.0000000	19.83882
7.788000	-20.00584	-0.1366754	0.0000000	19.98547
7.814668	-20.00617	-0.1364934	0.0000000	19.88762
7.841332	-20.00624	-0.1366067	0.0000000	19.91509
7.868000	-20.00691	-0.1365243	0.0000000	20.22765
7.894668	-20.00477	-0.1364026	0.0000000	19.89760
7.921332	-20.00436	-0.1363805	0.0000000	20.14457
7.948000	-20.00650	-0.1363249	0.0000000	19.87562
7.974668	-20.00516	-0.1363251	0.0000000	19.90567
8.001334	-20.00548	-0.1363032	0.0000000	19.95261
8.028000	-20.00669	-0.1362972	0.0000000	19.95599
8.054666	-20.00633	-0.1361696	0.0000000	20.20313
8.081332	-20.00621	-0.1362314	0.0000000	19.90460
8.108000	-20.00592	-0.1361356	0.0000000	20.14336
8.134668	-20.00739	-0.1359065	0.0000000	19.94455
8.161332	-20.00733	-0.1359443	0.0000000	19.92408
8.188000	-20.00525	-0.1360300	0.0000000	19.96144
8.214668	-20.00587	-0.1358894	0.0000000	19.89218
8.241332	-20.00602	-0.1358148	0.0000000	20.15036
8.268000	-20.00675	-0.1357802	0.0000000	19.84348
8.294666	-20.00630	-0.1358269	0.0000000	20.09846
8.321332	-20.00662	-0.1357032	0.0000000	19.90634
8.348000	-20.00698	-0.1356510	0.0000000	19.95914
8.374666	-20.00612	-0.1355930	0.0000000	20.04066
8.401334	-20.00526	-0.1355858	0.0000000	19.91322
8.428000	-20.00540	-0.1354213	0.0000000	20.17881
8.454668	-20.00657	-0.1355004	0.0000000	19.88244
8.481334	-20.00556	-0.1355202	0.0000000	20.11819
8.508000	-20.00667	-0.1353503	0.0000000	19.85336
8.534668	-20.00682	-0.1352631	0.0000000	19.93701
8.561334	-20.00493	-0.1353271	0.0000000	19.95306
8.588000	-20.00797	-0.1352357	0.0000000	19.93586
8.614668	-20.00676	-0.1349807	0.0000000	20.18154
8.641334	-20.00764	-0.1351030	0.0000000	19.96426
8.668000	-20.00586	-0.1349604	0.0000000	20.20037
8.694668	-20.00690	-0.1348726	0.0000000	19.89588
8.721332	-20.00566	-0.1349059	0.0000000	19.95667
8.748000	-20.00670	-0.1349047	0.0000000	19.88642
8.774668	-20.00660	-0.1348563	0.0000000	19.98659
8.801334	-20.00664	-0.1348634	0.0000000	20.18150
8.828000	-20.00661	-0.1347314	0.0000000	19.89261
8.854668	-20.00541	-0.1346300	0.0000000	20.09773
8.881332	-20.00710	-0.1345630	0.0000000	19.88989
8.908000	-20.00514	-0.1344917	0.0000000	19.87665
8.934668	-20.00625	-0.1344089	0.0000000	20.14021
8.961334	-20.00575	-0.1344810	0.0000000	19.89794
8.988000	-20.00728	-0.1345007	0.0000000	19.99638
9.014668	-20.00668	-0.1345676	0.0000000	19.90847
9.041332	-20.00658	-0.1346769	0.0000000	19.89696
9.068000	-20.00694	-0.1346555	0.0000000	20.06411
9.094666	-20.00748	-0.1345410	0.0000000	19.89845
9.121332	-20.00687	-0.1345570	0.0000000	20.27036
9.147999	-20.00624	-0.1345128	0.0000000	19.93502
9.174668	-20.00740	-0.1344530	0.0000000	20.10408
9.201332	-20.00668	-0.1343336	0.0000000	19.89704
9.228000	-20.00625	-0.1343646	0.0000000	19.93785
9.254666	-20.00703	-0.1342026	0.0000000	20.00044
9.281332	-20.00668	-0.1341344	0.0000000	19.83494
9.307999	-20.00592	-0.1341184	0.0000000	20.20119
9.334668	-20.00693	-0.1340328	0.0000000	19.87706
9.361332	-20.00588	-0.1338799	0.0000000	20.16713
9.388000	-20.00660	-0.1340247	0.0000000	19.91632
9.414668	-20.00676	-0.1338266	0.0000000	20.13477
9.441334	-20.00604	-0.1339842	0.0000000	19.95410
9.468000	-20.00656	-0.1339891	0.0000000	19.93119
9.494668	-20.00636	-0.1339745	0.0000000	20.05086
9.521332	-20.00731	-0.1338574	0.0000000	19.95626
9.548000	-20.00694	-0.1339022	0.0000000	20.17362
9.574668	-20.00791	-0.1338852	0.0000000	19.89517
9.601334	-20.00702	-0.1336708	0.0000000	20.15265
9.628000	-20.00681	-0.1336912	0.0000000	19.91451
9.654668	-20.00711	-0.1334424	0.0000000	20.12231
9.681334	-20.00586	-0.1334804	0.0000000	19.92453
9.708000	-20.00667	-0.1335441	0.0000000	19.96151
9.734668	-20.00767	-0.1334603	0.0000000	20.04946
9.761334	-20.00653	-0.1334066	0.0000000	19.98138
9.788000	-20.00747	-0.1334454	0.0000000	19.90920
9.814668	-20.00666	-0.1332673	0.0000000	20.12059
9.841332	-20.00666	-0.1331077	0.0000000	19.87404
9.868000	-20.00624	-0.1330594	0.0000000	19.96728
9.894668	-20.00544	-0.1330458	0.0000000	19.89506
9.921332	-20.00733	-0.1329909	0.0000000	19.88624
9.947999	-20.00585	-0.1329253	0.0000000	20.11506
9.974668	-20.00477	-0.1329582	0.0000000	19.94376
10.00133	-20.00613	-0.1328281	0.0000000	20.18452
10.02800	-20.00050	-0.1240837	-3.105717	19.90907
10.05467	-19.96498	-0.1927011	-3.260981	20.11305
10.08133	-19.85844	-0.4326020	-5.371045	19.88924
10.10800	-19.68457	-0.3754773	-3.611005	20.04562
10.13467	-19.47501	-.06593448	-0.5148654	20.10409
10.16133	-19.23698	0.2751598	1.835363	19.95106
10.18800	-18.97056	0.6566304	3.939570	20.03836
10.21467	-18.68363	1.061121	5.911816	19.99158
10.24133	-18.38070	1.449202	7.616352	20.17450
10.26800	-18.06308	1.795325	9.011281	19.83772
10.29467	-17.73252	2.108212	10.20913	20.19084
10.32133	-17.39318	2.381943	11.20833	19.88086
10.34800	-17.04709	2.624150	12.05365	20.08287
10.37467	-16.69157	2.833152	12.76056	19.84141
10.40133	-16.32978	3.025706	13.40722	19.92682
10.42800	-15.96594	3.179740	13.89951	19.89607
10.45467	-15.59595	3.314911	14.32550	19.91921
10.48133	-15.22161	3.436852	14.71067	19.98323
10.50800	-14.84398	3.545496	15.05263	20.02677
10.53467	-14.46629	3.649768	15.38863	20.18606
10.56133	-14.08499	3.717774	15.57795	19.90739
10.58800	-13.70082	3.784460	15.77828	20.14760
10.61467	-13.31442	3.844590	15.95786	19.89833
10.64134	-12.92854	3.902180	16.12591	20.10194
10.66800	-12.54058	3.948375	16.26746	19.89081
10.69467	-12.15090	3.994470	16.41317	19.95464
10.72133	-11.76084	4.024891	16.49394	19.97390
10.74800	-11.36752	4.066946	16.63004	19.95075
10.77467	-10.97596	4.095856	16.71220	19.95961
10.80133	-10.58404	4.127869	16.81345	19.99494
10.82800	-10.19031	4.149576	16.87352	20.17649
10.85467	-9.796439	4.176952	16.97227	19.93735
10.88133	-9.403075	4.196641	17.02948	20.15086
10.90800	-9.005048	4.217432	17.08989	19.86928
10.93467	-8.612658	4.240090	17.16670	20.14218
10.96133	-8.216798	4.250980	17.20084	19.92225
10.98800	-7.820791	4.265778	17.24391	20.02417
11.01467	-7.424278	4.284370	17.31173	20.09219
11.04133	-7.027282	4.303039	17.37348	19.85430
11.06800	-6.633090	4.319882	17.43285	20.04578
11.09467	-6.234057	4.329396	17.46172	20.00390
11.12133	-5.838250	4.339866	17.49596	20.03966
11.14800	-5.442158	4.356438	17.55697	19.96356
11.17467	-5.043948	4.368230	17.59408	20.17655
11.20133	-4.645996	4.380914	17.64185	19.90703
11.22800	-4.249126	4.388750	17.66578	20.17500
11.25466	-3.850793	4.404866	17.72247	19.90629
11.28133	-3.452780	4.413374	17.74728	20.09536
11.30800	-3.055128	4.427104	17.80110	19.84362
11.33467	-2.656224	4.437953	17.83664	19.92621
11.36133	-2.256742	4.447197	17.86836	20.10281
11.38800	-1.859761	4.458105	17.90816	19.84129
11.41467	-1.462109	4.468150	17.94904	20.05223
11.44134	-1.061095	4.487736	18.02890	19.90725
11.46800	-0.6640495	4.493816	18.04677	20.01439
11.49467	-0.2664303	4.500969	18.07256	19.93876
11.52133	0.1320316	4.511597	18.11528	19.90506
11.54800	0.5313740	4.524086	18.16320	20.00099
11.57467	0.9303132	4.529326	18.18445	19.92961
11.60133	1.330327	4.539876	18.21900	20.15139
11.62800	1.726428	4.554391	18.27599	19.96364
11.65467	2.127447	4.562063	18.30767	20.15244
11.68134	2.525704	4.568636	18.32966	19.84500
11.70800	2.924734	4.578941	18.37036	20.20218
11.73467	3.324070	4.592684	18.42369	19.96933
11.76133	3.724442	4.599930	18.45164	20.17570
11.78800	4.123889	4.609433	18.48823	19.89443
11.81467	4.522012	4.618832	18.51881	20.11581
11.84133	4.920482	4.632070	18.57274	19.87774
11.86800	5.320261	4.640876	18.60408	19.89612
11.89467	5.719277	4.649142	18.64163	19.85962
11.92133	6.118822	4.658370	18.67463	19.96878
11.94800	6.517797	4.675888	18.74234	20.00676
11.97467	6.917310	4.683948	18.77228	20.01416
12.00133	7.316728	4.688910	18.79732	20.02573
12.02800	7.715864	4.699727	18.83921	19.98914
12.05466	8.117226	4.707537	18.86667	20.16072
12.08133	8.514228	4.716110	18.90476	19.91231
12.10800	8.913797	4.727903	18.95238	20.17386
12.13467	9.313345	4.735801	18.98071	19.89759
12.16133	9.712356	4.743925	19.01314	19.85659
12.18800	10.11332	4.753502	19.05490	19.96248
12.21467	10.51166	4.763883	19.09241	19.87975
12.24133	10.91116	4.777222	19.15038	19.90550
12.26800	11.31187	4.786846	19.18917	19.90753
12.29467	11.70894	4.797340	19.23462	19.94633
12.32133	12.10971	4.807385	19.27375	20.09067
12.34800	12.50805	4.820285	19.31998	19.98408
12.37466	12.90861	4.827746	19.35784	20.11817
12.40133	13.30630	4.840148	19.40280	19.97281
12.42800	13.70643	4.852764	19.45374	20.18421
12.45467	14.10608	4.862098	19.49151	19.96684
12.48134	14.50505	4.875653	19.54788	20.20975
12.50800	14.90512	4.887438	19.58835	19.89760
12.53467	15.30429	4.896424	19.62534	20.11543
12.56133	15.70298	4.909176	19.67242	19.83635
12.58800	16.10278	4.919447	19.71353	20.11622
12.61467	16.50287	4.931537	19.75947	19.85902
12.64134	16.90031	4.946861	19.81952	20.00958
12.66800	17.30210	4.959067	19.86825	19.85216
12.69467	17.70170	4.968446	19.90739	20.00780
12.72133	18.10155	4.979398	19.95571	19.93745
12.74800	18.50238	4.989139	19.99080	19.96395
12.77467	18.89976	5.002491	20.04286	19.91242
12.80133	19.29758	5.012438	20.08637	19.94256
12.82800	19.69929	5.022044	20.13000	19.98897
12.85466	20.09752	5.033904	20.17704	19.99407
12.88134	20.49662	5.048606	20.24238	20.00864
12.90800	20.89687	5.063133	20.28808	20.02058
12.93467	21.29714	5.074794	20.34489	20.08696
12.96133	21.69584	5.084582	20.39029	20.00606
12.98800	22.09451	5.101465	20.44995	20.18609
13.01467	22.49361	5.110078	20.48380	19.95676
13.04133	22.89260	5.122838	20.53453	20.17704
13.06800	23.29299	5.141052	20.61750	19.91972
13.09467	23.69184	5.152463	20.65828	20.20479
13.12133	24.09073	5.164066	20.70138	19.87161
13.14800	24.49000	5.185672	20.79099	20.24820
13.17466	24.88884	5.197805	20.83392	19.87958
13.20133	25.28867	5.210632	20.88906	20.14974
13.22800	25.68913	5.220262	20.92472	19.89814
13.25466	26.08676	5.246178	21.03036	20.09780
13.28133	26.48706	5.256080	21.06990	19.85262
13.30800	26.88475	5.267180	21.11791	20.10532
13.33467	27.28575	5.286703	21.19753	19.84573
13.36133	27.68484	5.306720	21.27480	20.00952
13.38800	28.08500	5.316297	21.31522	19.86764
13.41467	28.48219	5.331048	21.37836	20.01242
13.44133	28.88304	5.350541	21.45970	19.90606
13.46800	29.28290	5.366754	21.52127	19.91024
13.49467	29.68110	5.379440	21.57748	19.90181
13.52133	30.08066	5.394100	21.63445	19.91614
13.54800	30.47915	5.412166	21.71744	19.94431
13.57467	30.87876	5.433559	21.79996	19.94579
13.60133	31.27760	5.452341	21.87119	19.92074
13.62800	31.67678	5.469809	21.94399	19.93284
13.65466	32.07434	5.486654	22.01172	20.08520
13.68134	32.47327	5.502578	22.07121	19.87962
13.70800	32.87338	5.520826	22.14900	19.94736
13.73467	33.27253	5.543169	22.23791	19.88125
13.76134	33.67111	5.563716	22.32010	19.92978
13.78800	34.07062	5.581340	22.38812	20.09903
13.81467	34.46846	5.605451	22.48485	19.86891
13.84133	34.86939	5.620026	22.55016	20.11554
13.86800	35.26826	5.642704	22.64156	19.93512
13.89467	35.66649	5.657436	22.70521	20.13598
13.92133	36.06382	5.683282	22.80350	19.92386
13.94800	36.46348	5.705041	22.89062	20.08710
13.97467	36.86263	5.720462	22.96892	19.90729
14.00133	37.26088	5.745604	23.06820	20.10878
14.02800	37.66047	5.771566	23.16785	19.87826
14.05466	38.05863	5.786941	23.23491	19.98072
14.08133	38.45759	5.817255	23.36325	19.88000
14.10800	38.85648	5.833678	23.42118	19.94468
14.13467	39.25641	5.858360	23.53170	19.88584
14.16133	39.65296	5.888262	23.64930	19.96770
14.18800	40.05231	5.909246	23.74357	19.93747
14.21467	40.45122	5.934973	23.84134	19.97416
14.24133	40.84875	5.959288	23.94492	19.88991
14.26800	41.24687	5.986810	24.04953	19.96510
14.29466	41.64562	6.018355	24.18158	19.90048
14.32133	42.04496	6.044240	24.28814	19.97430
14.34800	42.44316	6.080803	24.43355	19.90837
14.37466	42.84178	6.097605	24.50223	19.98392
14.40133	43.23892	6.130600	24.64295	19.92480
14.42800	43.63886	6.158652	24.75378	19.95757
14.45467	44.03455	6.188044	24.87327	19.86316
14.48134	44.43408	6.227379	25.02985	19.90339
14.50800	44.83150	6.247748	25.11862	19.88750
14.53467	45.23007	6.286960	25.28396	19.95288
14.56134	45.62922	6.312244	25.38531	19.95111
14.58800	46.02590	6.348355	25.53452	19.95374
14.61467	46.42414	6.376850	25.65010	19.96766
14.64133	46.82101	6.414270	25.80930	19.88925
14.66800	47.21929	6.444138	25.93901	19.89323
14.69467	47.61844	6.477222	26.06914	19.93884
14.72133	48.01428	6.512984	26.21740	19.81528
14.74800	48.41247	6.553201	26.38347	19.98551
14.77467	48.81111	6.587824	26.52177	19.94802
14.80133	49.20886	6.624259	26.67348	19.99257
14.82800	49.60635	6.659869	26.80854	19.89056
14.85466	50.00467	6.694303	26.95068	19.92480
14.88134	50.40203	6.743411	27.15323	19.90740
14.90800	50.79914	6.772444	27.27490	19.96346
14.93467	51.19626	6.817592	27.45866	20.12368
14.96133	51.59470	6.861856	27.63172	19.83192
14.98800	51.99106	6.900868	27.79802	20.12518
15.01467	52.38816	6.936345	27.95358	19.90652
15.04133	52.78557	6.987292	28.15237	20.08533
15.06800	53.18416	7.029262	28.32698	19.91728
15.09467	53.58129	7.078453	28.52110	20.11430
15.12133	53.97746	7.115000	28.66878	19.84367
15.14800	54.37624	7.152276	28.82144	20.08181
15.17466	54.77289	7.212378	29.07485	19.87091
15.20133	55.16970	7.256441	29.24810	20.12994
15.22800	55.56626	7.302352	29.43352	19.86308
15.25466	55.96534	7.344640	29.60710	20.00396
15.28133	56.36138	7.392335	29.80784	19.87930
15.30800	56.75661	7.438416	30.00370	20.00905
15.33467	57.15425	7.484210	30.18338	19.90415
15.36133	57.55078	7.536075	30.40387	20.08652
15.38800	57.94812	7.578412	30.57185	19.89015
15.41467	58.34502	7.637653	30.81916	20.13264
15.44133	58.74234	7.688581	31.02872	19.89581
15.46800	59.13825	7.739224	31.24214	20.11151
15.49467	59.53515	7.801538	31.50278	19.85211
15.52133	59.93144	7.846906	31.69484	20.15906
15.54800	60.32622	7.900178	31.91816	19.89223
15.57467	60.72394	7.959161	32.16006	20.13374
15.60133	61.11982	8.021320	32.41250	19.85988
15.62800	61.51547	8.089444	32.69594	20.18234
15.65466	61.91126	8.139550	32.90460	19.86774
15.68134	62.30791	8.195175	33.13231	20.15590
15.70800	62.70302	8.263519	33.42136	19.90172
15.73467	63.09937	8.323976	33.66504	20.18909
15.76134	63.49484	8.391272	33.93222	19.84509
15.78800	63.89340	8.457066	34.21492	20.18246
15.81467	64.28574	8.522582	34.46197	19.94820
15.84133	64.68286	8.581481	34.72771	20.17038
15.86800	65.07790	8.662842	35.05955	19.96456
15.89467	65.47488	8.732580	35.35115	20.14830
15.92134	65.86939	8.786742	35.57785	19.96254
15.94800	66.26412	8.861141	35.88195	20.12263
15.97467	66.66022	8.930141	36.15977	19.98938
16.00133	67.05566	9.006928	36.48356	20.11025
16.02800	67.45050	9.082840	36.80214	19.97942
16.05466	67.84460	9.152836	37.08873	20.13413
16.08133	68.24098	9.233080	37.41670	19.91948
16.10800	68.63561	9.309590	37.74894	20.02825
16.13467	69.02988	9.383179	38.04198	19.97933
16.16133	69.42530	9.463649	38.37591	20.09766
16.18800	69.82016	9.544281	38.70770	19.98407
16.21467	70.21411	9.616718	39.00415	20.03218
16.24133	70.60806	9.700304	39.34833	19.88260
16.26800	71.00495	9.782195	39.67979	20.09296
16.29466	71.39880	9.866172	40.04461	19.91877
16.32133	71.79175	9.945049	40.36800	20.18024
16.34800	72.18764	10.02846	40.70997	19.85296
16.37466	72.58228	10.11607	41.07728	20.11653
16.40133	72.97621	10.20335	41.42844	19.87843
16.42800	73.36884	10.28979	41.78512	20.16240
16.45466	73.76342	10.36748	42.11319	19.88007
16.48133	74.15780	10.45806	42.47250	20.17062
16.50800	74.55240	10.54318	42.82492	19.91012
16.53466	74.94640	10.63753	43.21452	20.12642
16.56133	75.34114	10.73250	43.60294	19.98546
16.58800	75.73489	10.81663	43.95117	20.20046
16.61466	76.12854	10.91227	44.36186	19.98500
16.64133	76.52280	11.00206	44.71516	20.03880
16.66800	76.91730	11.09186	45.07706	19.91402
16.69466	77.30958	11.17978	45.43787	20.01722
16.72133	77.70344	11.27488	45.83835	19.96375
16.74800	78.09822	11.36080	46.19049	19.93442
16.77466	78.49144	11.45847	46.59416	19.94949
16.80133	78.88547	11.55818	46.99850	19.93796
16.82800	79.27881	11.64816	47.37086	19.95863
16.85466	79.67225	11.74678	47.78585	19.91948
16.88133	80.06594	11.84226	48.16690	20.00418
16.90800	80.45999	11.93601	48.55167	19.85065
16.93466	80.85343	12.03825	48.97998	20.07921
16.96133	81.24676	12.12177	49.30922	19.88276
16.98800	81.64185	12.21790	49.69256	20.23504
17.01466	82.03430	12.32543	50.13350	19.87493
17.04133	82.42716	12.41468	50.49786	20.14289
17.06800	82.82062	12.51702	50.92065	19.94961
17.09466	83.21488	12.61252	51.31876	20.16590
17.12133	83.60856	12.70726	51.70022	19.85989
17.14800	84.00171	12.80440	52.11377	20.19516
17.17466	84.39500	12.89965	52.49966	19.99102
17.20133	84.78834	12.99845	52.88928	20.05127
17.22800	85.18195	13.10466	53.31914	19.97932
17.25466	85.57572	13.19469	53.67443	20.04148
17.28133	85.96899	13.28927	54.05771	19.95981
17.30800	86.36418	13.37819	54.43894	20.01209
17.33466	86.75629	13.46423	54.77896	19.91649
17.36133	87.15018	13.57597	55.23162	19.88760
17.38800	87.54343	13.66615	55.58882	19.87518
17.41466	87.93569	13.76382	55.98461	19.85808
17.44133	88.32984	13.85359	56.35523	20.32405
17.46800	88.72397	13.95396	56.74418	19.86366
17.49466	89.11832	14.04156	57.10367	20.14518
17.52133	89.51125	14.14260	57.49218	19.91979
17.54800	89.90470	14.23672	57.87994	20.09365
17.57466	90.29931	14.33339	58.26956	19.92146
17.60133	90.69380	14.41626	58.59537	20.15494
17.62800	91.08770	14.50383	58.94508	19.91945
17.65466	91.48043	14.59504	59.29543	20.17223
17.68133	91.87506	14.68508	59.66699	19.94398
17.70800	92.26922	14.77770	60.03368	20.16287
17.73466	92.66236	14.85985	60.35257	19.95117
17.76133	93.05809	14.95183	60.70680	20.02139
17.78800	93.45112	15.03827	61.06238	19.89567
17.81466	93.84699	15.12580	61.42051	19.85957
17.84133	94.24030	15.20349	0.0000000	19.89425
17.86800	94.63562	15.29858	0.0000000	19.89823
17.89466	95.03043	15.37380	0.0000000	20.13953
17.92133	95.42344	15.44788	0.0000000	19.88181
17.94800	95.81932	15.41942	0.0000000	20.07855
17.97467	96.21369	15.49431	0.0000000	19.93830
18.00133	96.60749	15.58775	0.0000000	20.13570
18.02800	96.99788	15.56085	0.0000000	19.93536
18.05466	97.36381	15.50361	0.0000000	20.19658
18.08133	97.66375	15.76969	0.0000000	19.95550
18.10800	97.89899	15.70532	0.0000000	20.13850
18.13466	98.09650	15.36316	0.0000000	19.99385
18.16133	98.26066	15.01371	0.0000000	20.14031
18.18800	98.39680	14.61534	0.0000000	19.96215
18.21466	98.50876	14.16838	0.0000000	19.99075
18.24133	98.60712	13.73054	0.0000000	19.99999
18.26800	98.68628	13.29960	0.0000000	19.95231
18.29466	98.75676	12.89355	0.0000000	20.04071
18.32133	98.81724	12.50976	0.0000000	19.87311
18.34800	98.86939	12.14957	0.0000000	20.10299
18.37466	98.91449	11.82019	0.0000000	19.91472
18.40133	98.95512	11.51102	0.0000000	20.19942
18.42800	98.99022	11.23093	0.0000000	19.85453
18.45466	99.02234	10.96579	0.0000000	20.18928
18.48133	99.05043	10.71940	0.0000000	19.95304
18.50800	99.07669	10.49634	0.0000000	20.13247
18.53466	99.10047	10.28214	0.0000000	19.96044
18.56133	99.12212	10.08282	0.0000000	19.96522
18.58800	99.14181	9.897378	0.0000000	19.91142
18.61466	99.15976	9.723316	0.0000000	19.94702
18.64133	99.18012	9.553684	0.0000000	19.88132
18.66800	99.19475	9.393368	0.0000000	20.15898
18.69466	99.20978	9.244188	0.0000000	19.91687
18.72133	99.22506	9.101391	0.0000000	20.12262
18.74800	99.23806	8.961059	0.0000000	19.99414
18.77466	99.24991	8.830079	0.0000000	20.09865
18.80133	99.26336	8.701158	0.0000000	19.95528
18.82800	99.27619	8.575781	0.0000000	20.00329
18.85466	99.28688	8.455478	0.0000000	19.91984
18.88133	99.29730	8.336732	0.0000000	19.88589
18.90800	99.30938	8.225122	0.0000000	20.14522
18.93466	99.31793	8.112046	0.0000000	19.86813
18.96133	99.32856	8.007195	0.0000000	20.10716
18.98800	99.33741	7.899121	0.0000000	19.83537
19.01466	99.34657	7.796416	0.0000000	20.20645
19.04133	99.35640	7.702372	0.0000000	19.94260
19.06800	99.36410	7.601053	0.0000000	20.16796
19.09466	99.37231	7.507990	0.0000000	20.02419
19.12133	99.38082	7.416337	0.0000000	20.00776
19.14800	99.39016	7.326184	0.0000000	19.91245
19.17466	99.39728	7.237924	0.0000000	19.85585
19.20133	99.40434	7.152166	0.0000000	19.85236
19.22800	99.41245	7.069624	0.0000000	19.93429
19.25466	99.42035	6.985462	0.0000000	19.86188
19.28133	99.42606	6.903495	0.0000000	20.10463
19.30800	99.43136	6.826461	0.0000000	19.94712
19.33466	99.43964	6.746604	0.0000000	20.12737
19.36133	99.44594	6.669986	0.0000000	19.83424
19.38800	99.45148	6.597741	0.0000000	20.14806
19.41466	99.45672	6.524836	0.0000000	19.93702
19.44133	99.46400	6.453750	0.0000000	20.14835
19.46800	99.46897	6.384087	0.0000000	19.96974
19.49466	99.47434	6.313793	0.0000000	19.97862
19.52133	99.47993	6.245428	0.0000000	19.92008
19.54800	99.48562	6.179419	0.0000000	19.95238
19.57466	99.49009	6.115078	0.0000000	20.02898
19.60133	99.49545	6.049631	0.0000000	19.91046
19.62800	99.49994	5.988764	0.0000000	20.10961
19.65466	99.50652	5.929000	0.0000000	19.89469
19.68133	99.51004	5.868674	0.0000000	20.16878
19.70800	99.51564	5.807492	0.0000000	19.97039
19.73466	99.51932	5.748229	0.0000000	20.09654
19.76133	99.52503	5.691715	0.0000000	20.09826
19.78800	99.52951	5.637020	0.0000000	19.88374
19.81466	99.53181	5.578010	0.0000000	19.98850
19.84133	99.53757	5.527937	0.0000000	19.90513
19.86800	99.54191	5.470376	0.0000000	20.13678
19.89466	99.54609	5.420899	0.0000000	19.88635
19.92133	99.54952	5.369102	0.0000000	20.12606
19.94800	99.55332	5.314978	0.0000000	19.89992
19.97467	99.55887	5.266895	0.0000000	20.05649
20.00133	99.56170	5.217657	0.0000000	19.92834
20.02800	99.56671	5.170452	0.0000000	19.98102
20.05466	99.56848	5.122206	0.0000000	19.93268
20.08133	99.57196	5.072232	0.0000000	19.87025
20.10800	99.57730	5.030664	0.0000000	20.01455
20.13466	99.57916	4.985030	0.0000000	19.92185
20.16133	99.58458	4.938860	0.0000000	20.08763
20.18800	99.58634	4.894402	0.0000000	19.89290
20.21466	99.59125	4.852394	0.0000000	20.14869
20.24133	99.59270	4.809219	0.0000000	19.99629
20.26800	99.59626	4.767743	0.0000000	20.00060
20.29466	99.59958	4.725709	0.0000000	19.95626
20.32133	99.60332	4.686166	0.0000000	19.90842
20.34800	99.60624	4.645333	0.0000000	20.15810
20.37466	99.60916	4.604696	0.0000000	19.87201
20.40133	99.61366	4.565587	0.0000000	20.11868
20.42800	99.61520	4.529290	0.0000000	19.85744
20.45466	99.61818	4.490103	0.0000000	20.15372
20.48133	99.62100	4.452344	0.0000000	20.02389
20.50800	99.62456	4.413842	0.0000000	20.06027
20.53466	99.62712	4.377990	0.0000000	19.92864
20.56133	99.62906	4.343786	0.0000000	19.91724
20.58800	99.63241	4.306453	0.0000000	20.10908
20.61467	99.63524	4.273447	0.0000000	19.92146
20.64133	99.63703	4.238194	0.0000000	20.16319
20.66800	99.63901	4.203880	0.0000000	19.90869
20.69466	99.64340	4.170572	0.0000000	20.16429
20.72133	99.64472	4.139256	0.0000000	19.94249
20.74800	99.64813	4.109402	0.0000000	19.96134
20.77466	99.65111	4.072058	0.0000000	19.93803
20.80133	99.65253	4.044406	0.0000000	19.87018
20.82800	99.65493	4.013614	0.0000000	20.19378
20.85466	99.65842	3.980383	0.0000000	19.89030
20.88133	99.66038	3.955951	0.0000000	20.24618
20.90800	99.66268	3.922850	0.0000000	19.95826
20.93466	99.66562	3.891171	0.0000000	19.97184
20.96133	99.66541	3.861246	0.0000000	19.93008
20.98800	99.66905	3.835885	0.0000000	19.92108
21.01466	99.67325	3.808062	0.0000000	19.94732
21.04133	99.67316	3.778408	0.0000000	19.89616
21.06800	99.67691	3.751636	0.0000000	19.99264
21.09466	99.67776	3.723465	0.0000000	20.07280
21.12133	99.67945	3.698546	0.0000000	19.98928
21.14800	99.68205	3.670379	0.0000000	19.96664
21.17466	99.68376	3.644104	0.0000000	20.11584
21.20133	99.68582	3.619318	0.0000000	20.01515
21.22800	99.68847	3.591678	0.0000000	20.06406
21.25466	99.68957	3.564540	0.0000000	19.96536
21.28133	99.69220	3.539851	0.0000000	20.12927
21.30800	99.69391	3.517563	0.0000000	19.90666
21.33466	99.69688	3.488491	0.0000000	19.96864
21.36133	99.69772	3.467055	0.0000000	19.96639
21.38800	99.69980	3.440752	0.0000000	19.99846
21.41466	99.70071	3.419231	0.0000000	20.09616
21.44133	99.70289	3.395192	0.0000000	19.99094
21.46800	99.70532	3.371230	0.0000000	20.04713
21.49466	99.70634	3.348834	0.0000000	19.98866
21.52133	99.70758	3.326628	0.0000000	20.10112
21.54800	99.70914	3.304272	0.0000000	19.90620
21.57466	99.71243	3.284438	0.0000000	20.00160
21.60133	99.71344	3.260170	0.0000000	20.06582
21.62800	99.71431	3.239114	0.0000000	19.96375
21.65466	99.71581	3.219216	0.0000000	20.07919
21.68133	99.71910	3.197560	0.0000000	19.93414
21.70800	99.72019	3.177316	0.0000000	20.01044
21.73466	99.72114	3.158150	0.0000000	20.00120
21.76133	99.72316	3.136604	0.0000000	19.95672
21.78800	99.72372	3.117712	0.0000000	19.97344
21.81466	99.72639	3.098236	0.0000000	20.22368
21.84133	99.72749	3.077793	0.0000000	20.09475
21.86800	99.72869	3.058496	0.0000000	20.01648
21.89467	99.73046	3.040702	0.0000000	19.92549
21.92133	99.73316	3.021399	0.0000000	19.88717
21.94800	99.73348	3.001106	0.0000000	19.92296
21.97467	99.73563	2.980364	0.0000000	20.14422
22.00133	99.73755	2.964020	0.0000000	20.00721
22.02800	99.73889	2.947373	0.0000000	20.05784
22.05466	99.73755	2.926846	0.0000000	19.96333
22.08133	99.74139	2.909376	0.0000000	20.02891
22.10800	99.74182	2.892182	0.0000000	19.93506
22.13466	99.74430	2.874193	0.0000000	19.97851
22.16133	99.74445	2.856722	0.0000000	20.00619
22.18800	99.74578	2.840998	0.0000000	20.02420
22.21467	99.74836	2.822010	0.0000000	20.05584
22.24133	99.74851	2.805422	0.0000000	20.00014
22.26800	99.75116	2.789901	0.0000000	20.05254
22.29466	99.75228	2.774290	0.0000000	19.93310
22.32133	99.75238	2.756216	0.0000000	20.00348
22.34800	99.75425	2.743344	0.0000000	20.06566
22.37466	99.75444	2.723713	0.0000000	20.00722
22.40133	99.75536	2.710759	0.0000000	20.06597
22.42800	99.75759	2.695478	0.0000000	20.02405
22.45466	99.75918	2.677283	0.0000000	20.11022
22.48133	99.76118	2.664203	0.0000000	19.90922
22.50800	99.76128	2.649010	0.0000000	20.00383
22.53466	99.76244	2.633848	0.0000000	20.06223
22.56133	99.76285	2.619553	0.0000000	19.99066
22.58800	99.76382	2.603614	0.0000000	20.06230
22.61467	99.76405	2.589840	0.0000000	19.91025
22.64133	99.76629	2.573654	0.0000000	19.90418
22.66800	99.76795	2.559787	0.0000000	19.91498
22.69466	99.76969	2.548253	0.0000000	19.99909
22.72133	99.77087	2.529338	0.0000000	20.05228
22.74800	99.77212	2.518675	0.0000000	19.94754
22.77466	99.77245	2.506224	0.0000000	20.13657
22.80133	99.77312	2.487878	0.0000000	19.90696
22.82800	99.77512	2.479448	0.0000000	19.97256
22.85466	99.77639	2.461473	0.0000000	19.99110
22.88133	99.77703	2.450842	0.0000000	20.00584
22.90800	99.77722	2.438626	0.0000000	20.07906
22.93466	99.78056	2.425169	0.0000000	19.98881
22.96133	99.77976	2.410461	0.0000000	20.05110
22.98800	99.78051	2.396552	0.0000000	19.91344
23.01466	99.78241	2.385820	0.0000000	20.17124
23.04133	99.78274	2.373435	0.0000000	19.97981
23.06800	99.78345	2.362032	0.0000000	19.99999
23.09466	99.78316	2.350622	0.0000000	20.27539
23.12133	99.78539	2.337166	0.0000000	19.93584
23.14800	99.78622	2.324008	0.0000000	19.88775
23.17466	99.78644	2.313468	0.0000000	19.95628
23.20133	99.78790	2.301584	0.0000000	19.99904
23.22800	99.78875	2.290070	0.0000000	20.02749
23.25466	99.78991	2.279897	0.0000000	19.98536
23.28133	99.79134	2.268691	0.0000000	20.14938
23.30800	99.79178	2.254970	0.0000000	19.92126
23.33466	99.79366	2.246020	0.0000000	20.13772
23.36133	99.79296	2.236800	0.0000000	20.03200
23.38800	99.79469	2.222830	0.0000000	19.99917
23.41466	99.79593	2.211042	0.0000000	20.06119
23.44133	99.79658	2.202513	0.0000000	19.97037
23.46800	99.79799	2.189673	0.0000000	19.98792
23.49466	99.79820	2.178574	0.0000000	19.91804
23.52133	99.79887	2.169640	0.0000000	20.11852
23.54800	99.79975	2.156702	0.0000000	19.90464
23.57466	99.80048	2.145478	0.0000000	20.05373
23.60133	99.80150	2.136651	0.0000000	19.93812
23.62800	99.80234	2.125912	0.0000000	19.91375
23.65466	99.80274	2.116173	0.0000000	20.09692
23.68133	99.80402	2.107525	0.0000000	19.92908
23.70800	99.80462	2.096248	0.0000000	20.21907
23.73466	99.80549	2.087089	0.0000000	19.90772
23.76133	99.80606	2.078864	0.0000000	19.82709
23.78800	99.80775	2.067480	0.0000000	20.08759
23.81466	99.80891	2.058793	0.0000000	19.90050
23.84133	99.80884	2.049292	0.0000000	20.20560
23.86800	99.80964	2.039645	0.0000000	19.97515
23.89467	99.81141	2.029816	0.0000000	19.98875
23.92133	99.81082	2.016837	0.0000000	19.94617
23.94800	99.81046	2.009618	0.0000000	20.04982
23.97467	99.81232	2.001664	0.0000000	20.20031
24.00133	99.81326	1.992245	0.0000000	19.94946
24.02800	99.81484	1.982802	0.0000000	20.02644
24.05466	99.81574	1.974521	0.0000000	19.99658
24.08133	99.81441	1.966792	0.0000000	19.91160
24.10800	99.81570	1.954998	0.0000000	20.10440
24.13466	99.81613	1.947702	0.0000000	19.85520
24.16133	99.81591	1.939417	0.0000000	20.16144
24.18800	99.81753	1.931231	0.0000000	19.93173
24.21467	99.81750	1.920424	0.0000000	19.85369
24.24133	99.81878	1.912283	0.0000000	20.07706
24.26800	99.82049	1.903414	0.0000000	19.93017
24.29466	99.82031	1.897265	0.0000000	20.10998
24.32133	99.82028	1.890183	0.0000000	20.11527
24.34800	99.82164	1.880061	0.0000000	19.94173
24.37466	99.82313	1.873222	0.0000000	20.10317
24.40133	99.82322	1.864991	0.0000000	19.94307
24.42800	99.82436	1.856570	0.0000000	20.16282
24.45466	99.82379	1.848961	0.0000000	19.97497
24.48133	99.82345	1.841638	0.0000000	19.88314
24.50800	99.82581	1.833022	0.0000000	19.95010
24.53466	99.82526	1.826238	0.0000000	19.92914
24.56133	99.82609	1.817970	0.0000000	20.17088
24.58800	99.82775	1.811094	0.0000000	19.94739
24.61467	99.82724	1.804546	0.0000000	19.96259
24.64133	99.82882	1.797097	0.0000000	19.90818
24.66800	99.83019	1.787518	0.0000000	19.89912
24.69466	99.82887	1.781047	0.0000000	20.15083
24.72133	99.83105	1.774117	0.0000000	20.00240
24.74800	99.83058	1.764792	0.0000000	20.01484
24.77466	99.83219	1.758329	0.0000000	19.97806
24.80133	99.83360	1.750150	0.0000000	19.86787
24.82800	99.83258	1.743922	0.0000000	20.16889
24.85466	99.83219	1.736816	0.0000000	19.93426
24.88133	99.83489	1.729389	0.0000000	20.06922
24.90800	99.83501	1.721891	0.0000000	19.96918
24.93466	99.83637	1.716281	0.0000000	19.89053
24.96133	99.83528	1.708798	0.0000000	20.15604
24.98800	99.83593	1.702401	0.0000000	19.99508
25.01466	99.83624	1.693732	0.0000000	20.02629
25.04133	99.83586	1.688668	0.0000000	19.90553
25.06800	99.83868	1.682398	0.0000000	19.89074
25.09466	99.83828	1.674723	0.0000000	20.08362
25.12133	99.83806	1.669042	0.0000000	19.96752
25.14800	99.84124	1.662908	0.0000000	20.06184
25.17466	99.84082	1.656197	0.0000000	19.92833
25.20133	99.84012	1.648872	0.0000000	19.91975
25.22800	99.84064	1.641751	0.0000000	20.10366
25.25466	99.84124	1.636719	0.0000000	19.86605
25.28133	99.84269	1.629903	0.0000000	20.03998
25.30800	99.84337	1.622170	0.0000000	19.96339
25.33466	99.84262	1.616893	0.0000000	19.85926
25.36133	99.84336	1.611184	0.0000000	20.16268
25.38800	99.84430	1.602679	0.0000000	19.93024
25.41466	99.84474	1.597565	0.0000000	20.10464
25.44133	99.84430	1.590574	0.0000000	19.95294
25.46800	99.84528	1.585101	0.0000000	19.83703
25.49466	99.84754	1.578125	0.0000000	20.14842
25.52133	99.84696	1.571461	0.0000000	19.94316
25.54800	99.84608	1.566077	0.0000000	20.03166
25.57466	99.84791	1.560187	0.0000000	19.89371
25.60133	99.84840	1.554212	0.0000000	20.11356
25.62800	99.84994	1.547178	0.0000000	20.20981
25.65466	99.84813	1.541978	0.0000000	19.95503
25.68133	99.84891	1.537000	0.0000000	20.01501
25.70800	99.84975	1.530334	0.0000000	19.99254
25.73466	99.84919	1.524122	0.0000000	19.90058
25.76133	99.85118	1.518410	0.0000000	20.18394
25.78800	99.85126	1.512215	0.0000000	20.00346
25.81466	99.85149	1.507222	0.0000000	19.87281
25.84133	99.85157	1.500105	0.0000000	19.90071
25.86800	99.85175	1.494695	0.0000000	19.91528
25.89466	99.85268	1.489742	0.0000000	20.18874
25.92133	99.85322	1.482483	0.0000000	19.94064
25.94800	99.85428	1.477301	0.0000000	19.91747
25.97467	99.85431	1.471997	0.0000000	20.18900
26.00133	99.85495	1.466394	0.0000000	20.00124
26.02800	99.85391	1.461159	0.0000000	19.88495
26.05466	99.85519	1.456068	0.0000000	20.08927
26.08133	99.85630	1.450764	0.0000000	19.93185
26.10800	99.85675	1.445454	0.0000000	20.13976
26.13467	99.85750	1.440119	0.0000000	19.94389
26.16133	99.85705	1.435008	0.0000000	19.87651
26.18800	99.85694	1.429934	0.0000000	20.08898
26.21467	99.85761	1.424810	0.0000000	19.87862
26.24133	99.85725	1.419846	0.0000000	20.02356
26.26800	99.85772	1.414590	0.0000000	19.95659
26.29466	99.85944	1.409550	0.0000000	19.99580
26.32133	99.85930	1.404167	0.0000000	20.21980
26.34800	99.85946	1.399043	0.0000000	19.93328
26.37467	99.85993	1.392981	0.0000000	20.04617
26.40133	99.86038	1.388106	0.0000000	19.95840
26.42800	99.86085	1.383161	0.0000000	19.86166
26.45466	99.86182	1.377984	0.0000000	20.15497
26.48133	99.86136	1.371454	0.0000000	19.96833
26.50800	99.86082	1.366748	0.0000000	19.92974
26.53466	99.86157	1.362269	0.0000000	20.09116
26.56133	99.86410	1.357052	0.0000000	19.94214
26.58800	99.86376	1.352268	0.0000000	20.14889
26.61467	99.86258	1.347792	0.0000000	19.92261
26.64133	99.86316	1.343152	0.0000000	19.84033
26.66800	99.86329	1.338252	0.0000000	20.10206
26.69466	99.86411	1.333343	0.0000000	19.93492
26.72133	99.86466	1.328744	0.0000000	20.12191
26.74800	99.86468	1.324286	0.0000000	19.97613
26.77466	99.86519	1.318965	0.0000000	19.93258
26.80133	99.86574	1.314452	0.0000000	20.14202
26.82800	99.86664	1.309760	0.0000000	19.93993
26.85466	99.86584	1.305373	0.0000000	20.02543
26.88133	99.86559	1.300581	0.0000000	20.09230
26.90800	99.86665	1.296173	0.0000000	19.93562
26.93466	99.86796	1.291223	0.0000000	20.18822
26.96133	99.86788	1.286477	0.0000000	19.94878
26.98800	99.86788	1.282108	0.0000000	19.85903
27.01467	99.86803	1.277842	0.0000000	20.12909
27.04133	99.86801	1.273478	0.0000000	19.88958
27.06800	99.86894	1.269046	0.0000000	20.11082
27.09466	99.86968	1.264872	0.0000000	19.98684
27.12133	99.86809	1.260516	0.0000000	19.88771
27.14800	99.87078	1.256264	0.0000000	20.13640
27.17466	99.87098	1.251877	0.0000000	19.95156
27.20133	99.87036	1.247631	0.0000000	19.94466
27.22800	99.87149	1.243244	0.0000000	20.04456
27.25466	99.87168	1.239115	0.0000000	19.90061
27.28133	99.87176	1.234859	0.0000000	20.18178
27.30800	99.87157	1.230508	0.0000000	19.96469
27.33466	99.87159	1.226412	0.0000000	19.84659
27.36133	99.87134	1.222172	0.0000000	20.09336
27.38800	99.87203	1.218062	0.0000000	19.92744
27.41467	99.87261	1.213860	0.0000000	20.01164
27.44133	99.87254	1.209702	0.0000000	19.97186
27.46800	99.87381	1.205753	0.0000000	20.02544
27.49466	99.87368	1.201660	0.0000000	19.98516
27.52133	99.87456	1.197723	0.0000000	19.81721
27.54800	99.87430	1.193573	0.0000000	20.20021
27.57466	99.87344	1.189742	0.0000000	20.14022
27.60133	99.87535	1.185986	0.0000000	19.90443
27.62800	99.87434	1.181905	0.0000000	19.89488
27.65466	99.87564	1.178066	0.0000000	20.01449
27.68133	99.87558	1.174142	0.0000000	20.00658
27.70800	99.87741	1.170544	0.0000000	19.88866
27.73466	99.87738	1.166466	0.0000000	20.19774
27.76133	99.87719	1.162798	0.0000000	19.90383
27.78800	99.87631	1.158975	0.0000000	19.94500
27.81466	99.87726	1.155139	0.0000000	20.09025
27.83967	99.87916	1.151506	0.0000000	20.13333